<?xml version="1.0" ?>
<!-- =================================================================================== -->
<!-- |    This document was autogenerated by xacro from /catkin_ws/src/human_description/urdf/human.urdf.xacro | -->
<!-- |    EDITING THIS FILE BY HAND IS NOT RECOMMENDED                                 | -->
<!-- =================================================================================== -->
<robot name="human">
    <link name="robot_root" />
    <joint name="hand_1_joint" type="floating">
        <parent link="robot_root" />
        <child link="hand_1" />
        <origin rpy="0   0   0" xyz="0.0 0.0 0.0" />
    </joint>
    <link name="hand_1" />
    <joint name="hand_2_joint" type="floating">
        <parent link="robot_root" />
        <child link="hand_2" />
        <origin rpy="0   0   0" xyz="0.0 0.0 0.0" />
    </joint>
    <link name="hand_2" />
    <transmission name="trans_hand_1_joint">
        <type>transmission_interface/SimpleTransmission</type>
        <joint name="hand_1_joint">
            <hardwareInterface>hardware_interface/EffortJointInterface</hardwareInterface>
        </joint>
        <actuator name="hand_1_joint_motor">
            <hardwareInterface>hardware_interface/EffortJointInterface</hardwareInterface>
            <mechanicalReduction>1</mechanicalReduction>
        </actuator>
    </transmission>
    <transmission name="trans_hand_2_joint">
        <type>transmission_interface/SimpleTransmission</type>
        <joint name="hand_2_joint">
            <hardwareInterface>hardware_interface/EffortJointInterface</hardwareInterface>
        </joint>
        <actuator name="hand_2_joint_motor">
            <hardwareInterface>hardware_interface/EffortJointInterface</hardwareInterface>
            <mechanicalReduction>1</mechanicalReduction>
        </actuator>
    </transmission>
    <gazebo>
        <plugin name="gazebo_ros_control">
            <robotNamespace>/</robotNamespace>
        </plugin>
    </gazebo>
</robot>

